Workbook
Name Company_Name: #REF!
Name Net_Profit: #REF!
Name RowTitleRegion1..C3: #REF!
Name RowTitleRegion1..C3.3: #REF!
Name RowTitleRegion1..C3.4: #REF!
Name RowTitleRegion1..C3.5: #REF!
Name RowTitleRegion1..C4: #REF!
Name RowTitleRegion2..H20: #REF!
Name Sales_Revenue: SUMIFS(#REF!,#REF!,"Sales Revenue")
Name Title1: #REF!
Name Title2: #REF!
Name Title3: #REF!
Name Title4: #REF!
Name Title5: #REF!
Name Title6: #REF!
Name Total_Cost_Sales: #REF!
Name Total_General_and_Administrative: #REF!
Name Total_Gross_Profit: #REF!
Name Total_Income_Operations: #REF!
Name Total_Operating_Expenses: #REF!
Name Total_Other_Expenses: #REF!
Name Total_Other_Income: #REF!
Name Total_Research_and_Development: #REF!
Name Total_Sales_and_Marketing: #REF!
Name Total_Sales_Revenue: #REF!
Name Total_Taxes: #REF!
Name Workbook_Dates: #REF!
Name Workbook_Title: #REF!

Sheet MODEL>>

Sheet Outputs
J2: =Control!D2 -> Basic Financial Model
J3: =MID(CELL("filename",A1),FIND("]",CELL("filename",A1))+1,255) -> Outputs
J4: =Control!D4 -> Financial Scenario: Base Case
J5: Calendar Year | N5: =N13 -> CY26 | O5: =O13 -> CY26 | P5: =P13 -> CY26 | Q5: =Q13 -> CY26 | R5: =R13 -> CY26 | S5: =S13 -> CY26 | T5: =T13 -> CY27 | U5: =U13 -> CY27 | ... KI5: =KI13 -> CY49
J6: Financial Year | N6: =N14 -> FY27 | O6: =O14 -> FY27 | P6: =P14 -> FY27 | Q6: =Q14 -> FY27 | R6: =R14 -> FY27 | S6: =S14 -> FY27 | T6: =T14 -> FY27 | U6: =U14 -> FY27 | ... KI6: =KI14 -> FY50
B7: Sum Project | C7: Sum Loan | D7: Average | E7: Max | F7: Min | G7: Ref | H7: Units | J7: Date | N7: =TEXT(N12,"mmm-yy") -> Jul-26 | O7: =TEXT(O12,"mmm-yy") -> Aug-26 | P7: =TEXT(P12,"mmm-yy") -> Sep-26 | Q7: =TEXT(Q12,"mmm-yy") -> Oct-26 | R7: =TEXT(R12,"mmm-yy") -> Nov-26 | S7: =TEXT(S12,"mmm-yy") -> Dec-26 | T7: =TEXT(T12,"mmm-yy") -> Jan-27 | U7: =TEXT(U12,"mmm-yy") -> Feb-27 | ... KI7: =TEXT(KI12,"mmm-yy") -> Dec-49
J9: Periods
E11: =MAX(N11:KI11) -> 54758 | F11: =MIN(N11:KI11) -> 46204 | H11: Date | M11: Start of period | N11: =DATE(2026,7,1) -> 46204 | O11: =N12+1 -> 46235 | P11: =O12+1 -> 46266 | Q11: =P12+1 -> 46296 | R11: =Q12+1 -> 46327 | S11: =R12+1 -> 46357 | T11: =S12+1 -> 46388 | U11: =T12+1 -> 46419 | V11: =U12+1 -> 46447 | ... KI11: =KH12+1 -> 54758
E12: =MAX(N12:KI12) -> 54788 | F12: =MIN(N12:KI12) -> 46234 | H12: Date | M12: End of period | N12: =EOMONTH(N11,0) -> 46234 | O12: =EOMONTH(O11,0) -> 46265 | P12: =EOMONTH(P11,0) -> 46295 | Q12: =EOMONTH(Q11,0) -> 46326 | R12: =EOMONTH(R11,0) -> 46356 | S12: =EOMONTH(S11,0) -> 46387 | T12: =EOMONTH(T11,0) -> 46418 | U12: =EOMONTH(U11,0) -> 46446 | ... KI12: =EOMONTH(KI11,0) -> 54788
H13: Date | M13: Calendar year | N13: ="CY"&RIGHT(YEAR(N11),2) -> CY26 | O13: ="CY"&RIGHT(YEAR(O11),2) -> CY26 | P13: ="CY"&RIGHT(YEAR(P11),2) -> CY26 | Q13: ="CY"&RIGHT(YEAR(Q11),2) -> CY26 | R13: ="CY"&RIGHT(YEAR(R11),2) -> CY26 | S13: ="CY"&RIGHT(YEAR(S11),2) -> CY26 | T13: ="CY"&RIGHT(YEAR(T11),2) -> CY27 | U13: ="CY"&RIGHT(YEAR(U11),2) -> CY27 | ... KI13: ="CY"&RIGHT(YEAR(KI11),2) -> CY49
H14: Date | M14: Financial Year | N14: ="FY"&IF(MONTH(N11)>6,RIGHT(YEAR(N11)+1,2),RIGHT(YEAR(N11),2)) -> FY27 | O14: ="FY"&IF(MONTH(O11)>6,RIGHT(YEAR(O11)+1,2),RIGHT(YEAR(O11),2)) -> FY27 | P14: ="FY"&IF(MONTH(P11)>6,RIGHT(YEAR(P11)+1,2),RIGHT(YEAR(P11),2)) -> FY27 | Q14: ="FY"&IF(MONTH(Q11)>6,RIGHT(YEAR(Q11)+1,2),RIGHT(YEAR(Q11),2)) -> FY27 | R14: ="FY"&IF(MONTH(R11)>6,RIGHT(YEAR(R11)+1,2),RIGHT(YEAR(R11),2)) -> FY27 | S14: ="FY"&IF(MONTH(S11)>6,RIGHT(YEAR(S11)+1,2),RIGHT(YEAR(S11),2)) -> FY27 | T14: ="FY"&IF(MONTH(T11)>6,RIGHT(YEAR(T11)+1,2),RIGHT(YEAR(T11),2)) -> FY27 | U14: ="FY"&IF(MONTH(U11)>6,RIGHT(YEAR(U11)+1,2),RIGHT(YEAR(U11),2)) -> FY27 | ... KI14: ="FY"&IF(MONTH(KI11)>6,RIGHT(YEAR(KI11)+1,2),RIGHT(YEAR(KI11),2)) -> FY50
H15: Days | M15: Days in Period | N15: =N12-N11+1 -> 31 | O15: =O12-O11+1 -> 31 | P15: =P12-P11+1 -> 30 | Q15: =Q12-Q11+1 -> 31 | R15: =R12-R11+1 -> 30 | S15: =S12-S11+1 -> 31 | T15: =T12-T11+1 -> 31 | U15: =U12-U11+1 -> 28 | ... KI15: =KI12-KI11+1 -> 31
H16: % pa | M16: Inflation index
J18: Financial Statements
K20: Income Statement - Inputs
L22: Volumes and Prices
H23: M Ltrs | M23: Sales Volume | N23: =Inputs!K24 -> 41 | O23: =Inputs!L24 -> 37 | P23: =Inputs!M24 -> 51 | Q23: =Inputs!N24 -> 74 | R23: =Inputs!O24 -> 36 | S23: =Inputs!P24 -> 33 | T23: =Inputs!Q24 -> 43 | U23: =Inputs!R24 -> 48 | ... KI23: =Inputs!KF24 -> 53
H24: USD/Ltr, real | M24: Sales Price | N24: =Inputs!K40 -> 2.35 | O24: =Inputs!L40 -> 2.35 | P24: =Inputs!M40 -> 2.35 | Q24: =Inputs!N40 -> 2.35 | R24: =Inputs!O40 -> 2.35 | S24: =Inputs!P40 -> 2.35 | T24: =Inputs!Q40 -> 2.3 | U24: =Inputs!R40 -> 2.3 | ... KI24: =Inputs!KF40 -> 2.25
H25: USD/Ltr, real | M25: Unit Cost | N25: =Inputs!K56 -> -0.28887274 | O25: =Inputs!L56 -> -0.26384952 | P25: =Inputs!M56 -> -0.36179302 | Q25: =Inputs!N56 -> -0.51930819 | R25: =Inputs!O56 -> -0.25707948 | S25: =Inputs!P56 -> -0.23743734 | T25: =Inputs!Q56 -> -0.30209971 | U25: =Inputs!R56 -> -0.33805637 | ... KI25: =Inputs!KF56 -> -0.37564673
H26: USDm, real | M26: Variable Costs | N26: =N23*N25 -> -11.843782 | O26: =O23*O25 -> -9.7624321 | P26: =P23*P25 -> -18.451444 | Q26: =Q23*Q25 -> -38.428806 | R26: =R23*R25 -> -9.2548614 | S26: =S23*S25 -> -7.8354324 | T26: =T23*T25 -> -12.990287 | U26: =U23*U25 -> -16.226706 | ... KI26: =KI23*KI25 -> -19.909277
H27: USDm, real | M27: Fixed Costs | N27: =Inputs!K72 -> -2.5 | O27: =Inputs!L72 -> -2.5 | P27: =Inputs!M72 -> -2.5 | Q27: =Inputs!N72 -> -2.5 | R27: =Inputs!O72 -> -2.5 | S27: =Inputs!P72 -> -2.5 | T27: =Inputs!Q72 -> -2.5 | U27: =Inputs!R72 -> -2.5 | ... KI27: =Inputs!KF72 -> -2.5
K29: Income Statement - to CFADS
L31: EBITDA
H32: USDm, real | M32: Revenue | N32: =N23*N24 -> 96.35 | O32: =O23*O24 -> 86.95 | P32: =P23*P24 -> 119.85 | Q32: =Q23*Q24 -> 173.9 | R32: =R23*R24 -> 84.6 | S32: =S23*S24 -> 77.55 | T32: =T23*T24 -> 98.9 | U32: =U23*U24 -> 110.4 | ... KI32: =KI23*KI24 -> 119.25
H33: USDm, real | M33: COGS | N33: =SUM(N26:N27) -> -14.343782 | O33: =SUM(O26:O27) -> -12.262432 | P33: =SUM(P26:P27) -> -20.951444 | Q33: =SUM(Q26:Q27) -> -40.928806 | R33: =SUM(R26:R27) -> -11.754861 | S33: =SUM(S26:S27) -> -10.335432 | T33: =SUM(T26:T27) -> -15.490287 | U33: =SUM(U26:U27) -> -18.726706 | ... KI33: =SUM(KI26:KI27) -> -22.409277
H34: USDm, real | M34: Total Income | N34: =SUM(N32:N33) -> 82.006218 | O34: =SUM(O32:O33) -> 74.687568 | P34: =SUM(P32:P33) -> 98.898556 | Q34: =SUM(Q32:Q33) -> 132.97119 | R34: =SUM(R32:R33) -> 72.845139 | S34: =SUM(S32:S33) -> 67.214568 | T34: =SUM(T32:T33) -> 83.409713 | U34: =SUM(U32:U33) -> 91.673294 | ... KI34: =SUM(KI32:KI33) -> 96.840723
H35: USDm, real | M35: SG&A | N35: =Inputs!K88 -> -2.625 | O35: =Inputs!L88 -> -2.625 | P35: =Inputs!M88 -> -2.625 | Q35: =Inputs!N88 -> -2.625 | R35: =Inputs!O88 -> -2.625 | S35: =Inputs!P88 -> -2.625 | T35: =Inputs!Q88 -> -2.625 | U35: =Inputs!R88 -> -2.625 | ... KI35: =Inputs!KF88 -> -2.625
H36: USDm, real | M36: Other | N36: =Inputs!K104 -> -2.1 | O36: =Inputs!L104 -> -2.1 | P36: =Inputs!M104 -> -2.1 | Q36: =Inputs!N104 -> -2.1 | R36: =Inputs!O104 -> -2.1 | S36: =Inputs!P104 -> -2.1 | T36: =Inputs!Q104 -> -2.1 | U36: =Inputs!R104 -> -2.1 | ... KI36: =Inputs!KF104 -> -2.1
H37: USDm, real | M37: Cash EBITDA | N37: =SUM(N34:N36) -> 77.281218 | O37: =SUM(O34:O36) -> 69.962568 | P37: =SUM(P34:P36) -> 94.173556 | Q37: =SUM(Q34:Q36) -> 128.24619 | R37: =SUM(R34:R36) -> 68.120139 | S37: =SUM(S34:S36) -> 62.489568 | T37: =SUM(T34:T36) -> 78.684713 | U37: =SUM(U34:U36) -> 86.948294 | ... KI37: =SUM(KI34:KI36) -> 92.115723
H38: USDm, real | M38: Capex | N38: =-Inputs!K120 -> -1 | O38: =-Inputs!L120 -> -1 | P38: =-Inputs!M120 -> -1 | Q38: =-Inputs!N120 -> -1 | R38: =-Inputs!O120 -> -1 | S38: =-Inputs!P120 -> -1 | T38: =-Inputs!Q120 -> -1 | U38: =-Inputs!R120 -> -1 | ... KI38: =-Inputs!KF120 -> -1
G39: =Control!H135 -> 0.3 | H39: USDm, real | M39: Tax (est.) | N39: =MIN(-N37*$G39,0) -> -23.184365 | O39: =MIN(-O37*$G39,0) -> -20.98877 | P39: =MIN(-P37*$G39,0) -> -28.252067 | Q39: =MIN(-Q37*$G39,0) -> -38.473858 | R39: =MIN(-R37*$G39,0) -> -20.436042 | S39: =MIN(-S37*$G39,0) -> -18.74687 | T39: =MIN(-T37*$G39,0) -> -23.605414 | U39: =MIN(-U37*$G39,0) -> -26.084488 | ... KI39: =MIN(-KI37*$G39,0) -> -27.634717
H40: USDm, real | M40: CFADS | N40: =SUM(N37:N39) -> 53.096852 | O40: =SUM(O37:O39) -> 47.973798 | P40: =SUM(P37:P39) -> 64.921489 | Q40: =SUM(Q37:Q39) -> 88.772336 | R40: =SUM(R37:R39) -> 46.684097 | S40: =SUM(S37:S39) -> 42.742697 | T40: =SUM(T37:T39) -> 54.079299 | U40: =SUM(U37:U39) -> 59.863806 | ... KI40: =SUM(KI37:KI39) -> 63.481006
K42: Cash Flow Statement
L44: Cash Flow Statement
H45: USDm, real | M45: Operating Cash Flows | N45: =N40 -> 53.096852 | O45: =O40 -> 47.973798 | P45: =P40 -> 64.921489 | Q45: =Q40 -> 88.772336 | R45: =R40 -> 46.684097 | S45: =S40 -> 42.742697 | T45: =T40 -> 54.079299 | U45: =U40 -> 59.863806 | ... KI45: =KI40 -> 63.481006
H46: USDm, real | M46: Investing Cash Flows | N46: =N38 -> -1 | O46: =O38 -> -1 | P46: =P38 -> -1 | Q46: =Q38 -> -1 | R46: =R38 -> -1 | S46: =S38 -> -1 | T46: =T38 -> -1 | U46: =U38 -> -1 | ... KI46: =KI38 -> -1
H47: USDm, real | M47: Financing Cash Flows | N47: =N81+N82+N110+N111+N112 -> 0 | O47: =O81+O82+O110+O111+O112 -> 0 | P47: =P81+P82+P110+P111+P112 -> 0 | Q47: =Q81+Q82+Q110+Q111+Q112 -> 0 | R47: =R81+R82+R110+R111+R112 -> 0 | S47: =S81+S82+S110+S111+S112 -> -35 | T47: =T81+T82+T110+T111+T112 -> 40 | U47: =U81+U82+U110+U111+U112 -> 0 | ... KI47: =KI81+KI82+KI110+KI111+KI112 -> 0
H48: USDm, real | M48: Opening Cash Balance | N48: 159.90315 | O48: =N50 -> 212 | P48: =O50 -> 258.9738 | Q48: =P50 -> 322.89529 | R48: =Q50 -> 410.66762 | S48: =R50 -> 456.35172 | T48: =S50 -> 463.09442 | U48: =T50 -> 556.17372 | V48: =U50 -> 615.03752 | ... KI48: =KH50 -> 19177.03
H49: USDm, real | M49: Net Cash Flow | N49: =SUM(N45:N47) -> 52.096852 | O49: =SUM(O45:O47) -> 46.973798 | P49: =SUM(P45:P47) -> 63.921489 | Q49: =SUM(Q45:Q47) -> 87.772336 | R49: =SUM(R45:R47) -> 45.684097 | S49: =SUM(S45:S47) -> 6.7426973 | T49: =SUM(T45:T47) -> 93.079299 | U49: =SUM(U45:U47) -> 58.863806 | ... KI49: =SUM(KI45:KI47) -> 62.481006
H50: USDm, real | M50: Closing Cash Balance | N50: =SUM(N48:N49) -> 212 | O50: =SUM(O48:O49) -> 258.9738 | P50: =SUM(P48:P49) -> 322.89529 | Q50: =SUM(Q48:Q49) -> 410.66762 | R50: =SUM(R48:R49) -> 456.35172 | S50: =SUM(S48:S49) -> 463.09442 | T50: =SUM(T48:T49) -> 556.17372 | U50: =SUM(U48:U49) -> 615.03752 | ... KI50: =SUM(KI48:KI49) -> 19239.511
...

Sheet Inputs
B2: Metrics | G2: =Control!$D$2 -> Basic Financial Model
G3: =MID(CELL("filename",$A$1),FIND("]",CELL("filename",$A$1))+1,255) -> Inputs
G4: =Control!$D$4 -> Financial Scenario: Base Case
G5: Calendar Year | K5: =K13 -> CY26 | L5: =L13 -> CY26 | M5: =M13 -> CY26 | N5: =N13 -> CY26 | O5: =O13 -> CY26 | P5: =P13 -> CY26 | Q5: =Q13 -> CY27 | R5: =R13 -> CY27 | ... KF5: =KF13 -> CY49
G6: Financial Year | K6: =K14 -> FY27 | L6: =L14 -> FY27 | M6: =M14 -> FY27 | N6: =N14 -> FY27 | O6: =O14 -> FY27 | P6: =P14 -> FY27 | Q6: =Q14 -> FY27 | R6: =R14 -> FY27 | ... KF6: =KF14 -> FY50
D7: Ref | E7: Units | G7: Date | K7: =TEXT(K12,"mmm-yy") -> Jul-26 | L7: =TEXT(L12,"mmm-yy") -> Aug-26 | M7: =TEXT(M12,"mmm-yy") -> Sep-26 | N7: =TEXT(N12,"mmm-yy") -> Oct-26 | O7: =TEXT(O12,"mmm-yy") -> Nov-26 | P7: =TEXT(P12,"mmm-yy") -> Dec-26 | Q7: =TEXT(Q12,"mmm-yy") -> Jan-27 | R7: =TEXT(R12,"mmm-yy") -> Feb-27 | ... KF7: =TEXT(KF12,"mmm-yy") -> Dec-49
G9: Periods
E11: Date | J11: Start of period | K11: =DATE(2026,7,1) -> 46204 | L11: =K12+1 -> 46235 | M11: =L12+1 -> 46266 | N11: =M12+1 -> 46296 | O11: =N12+1 -> 46327 | P11: =O12+1 -> 46357 | Q11: =P12+1 -> 46388 | R11: =Q12+1 -> 46419 | S11: =R12+1 -> 46447 | ... KF11: =KE12+1 -> 54758
E12: Date | J12: End of period | K12: =EOMONTH(K11,0) -> 46234 | L12: =EOMONTH(L11,0) -> 46265 | M12: =EOMONTH(M11,0) -> 46295 | N12: =EOMONTH(N11,0) -> 46326 | O12: =EOMONTH(O11,0) -> 46356 | P12: =EOMONTH(P11,0) -> 46387 | Q12: =EOMONTH(Q11,0) -> 46418 | R12: =EOMONTH(R11,0) -> 46446 | ... KF12: =EOMONTH(KF11,0) -> 54788
E13: Date | J13: Calendar year | K13: ="CY"&RIGHT(YEAR(K11),2) -> CY26 | L13: ="CY"&RIGHT(YEAR(L11),2) -> CY26 | M13: ="CY"&RIGHT(YEAR(M11),2) -> CY26 | N13: ="CY"&RIGHT(YEAR(N11),2) -> CY26 | O13: ="CY"&RIGHT(YEAR(O11),2) -> CY26 | P13: ="CY"&RIGHT(YEAR(P11),2) -> CY26 | Q13: ="CY"&RIGHT(YEAR(Q11),2) -> CY27 | R13: ="CY"&RIGHT(YEAR(R11),2) -> CY27 | ... KF13: ="CY"&RIGHT(YEAR(KF11),2) -> CY49
J14: Financial Year | K14: ="FY"&IF(MONTH(K11)>6,RIGHT(YEAR(K11)+1,2),RIGHT(YEAR(K11),2)) -> FY27 | L14: ="FY"&IF(MONTH(L11)>6,RIGHT(YEAR(L11)+1,2),RIGHT(YEAR(L11),2)) -> FY27 | M14: ="FY"&IF(MONTH(M11)>6,RIGHT(YEAR(M11)+1,2),RIGHT(YEAR(M11),2)) -> FY27 | N14: ="FY"&IF(MONTH(N11)>6,RIGHT(YEAR(N11)+1,2),RIGHT(YEAR(N11),2)) -> FY27 | O14: ="FY"&IF(MONTH(O11)>6,RIGHT(YEAR(O11)+1,2),RIGHT(YEAR(O11),2)) -> FY27 | P14: ="FY"&IF(MONTH(P11)>6,RIGHT(YEAR(P11)+1,2),RIGHT(YEAR(P11),2)) -> FY27 | Q14: ="FY"&IF(MONTH(Q11)>6,RIGHT(YEAR(Q11)+1,2),RIGHT(YEAR(Q11),2)) -> FY27 | R14: ="FY"&IF(MONTH(R11)>6,RIGHT(YEAR(R11)+1,2),RIGHT(YEAR(R11),2)) -> FY27 | ... KF14: ="FY"&IF(MONTH(KF11)>6,RIGHT(YEAR(KF11)+1,2),RIGHT(YEAR(KF11),2)) -> FY50
J15: Days in Period | K15: =K12-K11+1 -> 31 | L15: =L12-L11+1 -> 31 | M15: =M12-M11+1 -> 30 | N15: =N12-N11+1 -> 31 | O15: =O12-O11+1 -> 30 | P15: =P12-P11+1 -> 31 | Q15: =Q12-Q11+1 -> 31 | R15: =R12-R11+1 -> 28 | ... KF15: =KF12-KF11+1 -> 31
J16: Inflation index
G18: Inputs
H20: Sales Volume
J22: Chosen case | K22: =Control!H17 -> 1 | L22: {=INDEX(J26:J34,K22)} -> Base case
E23: M Ltrs | J23: Live Price | K23: {=INDEX(K26:K34,$K$22)} -> 41.267535 | L23: {=INDEX(L26:L34,$K$22)} -> 37.692788 | M23: {=INDEX(M26:M34,$K$22)} -> 51.684718 | N23: {=INDEX(N26:N34,$K$22)} -> 74.186884 | O23: {=INDEX(O26:O34,$K$22)} -> 36.72564 | P23: {=INDEX(P26:P34,$K$22)} -> 33.919621 | Q23: {=INDEX(Q26:Q34,$K$22)} -> 43.157101 | R23: {=INDEX(R26:R34,$K$22)} -> 48.293767 | ... KF23: {=INDEX(KF26:KF34,$K$22)} -> 53.663819
D24: 0 | E24: M Ltrs | J24: Bank Adjustment | K24: =INT(K23*(1+$D24)) -> 41 | L24: =INT(L23*(1+$D24)) -> 37 | M24: =INT(M23*(1+$D24)) -> 51 | N24: =INT(N23*(1+$D24)) -> 74 | O24: =INT(O23*(1+$D24)) -> 36 | P24: =INT(P23*(1+$D24)) -> 33 | Q24: =INT(Q23*(1+$D24)) -> 43 | R24: =INT(R23*(1+$D24)) -> 48 | ... KF24: =INT(KF23*(1+$D24)) -> 53
E26: M Ltrs | J26: Base case | K26: 41.267535 | L26: 37.692788 | M26: 51.684718 | N26: 74.186884 | O26: 36.72564 | P26: 33.919621 | Q26: 43.157101 | R26: 48.293767 | S26: 82.842122 | T26: 85.141491 | U26: 71.974816 | V26: 58.511833 | W26: 25.548062 | X26: 79.8058 | Y26: 86.091436 | Z26: 84.709527 | AA26: 69.221061 | AB26: 46.350018 | AC26: 37.957816 | AD26: 64.726348 | AE26: 26.716842 | AF26: 65.34932 | AG26: 29.069379 | AH26: 62.161903 | AI26: 31.902974 | AJ26: 65.734663 | AK26: 63.315313 | AL26: 34.021791 | AM26: 37.781185 | AN26: 35.933026 | AO26: 26.220593 | AP26: 64.310952 | AQ26: 47.31235 | AR26: 52.920734 | AS26: 50.073917 | AT26: 68.161871 | AU26: 81.771783 | AV26: 59.10227 | AW26: 76.179941 | AX26: 64.269497 | AY26: 87.769886 | AZ26: 54.459037 | BA26: 26.065621 | BB26: 70.319737 | BC26: 94.036111 | BD26: 45.475474 | BE26: 61.246484 | BF26: 54.71625 | BG26: 76.004109 | BH26: 97.036793 | BI26: 68.863624 | BJ26: 38.708616 | BK26: 49.36803 | BL26: 56.301251 | BM26: 47.224234 | BN26: 63.6732 | BO26: 72.997663 | BP26: 36.284059 | BQ26: 35.060017 | BR26: 40.501291 | BS26: 42.77548 | BT26: 38.981665 | BU26: 46.281632 | BV26: 81.927311 | BW26: 62.651873 | BX26: 41.494072 | BY26: 49.205618 | BZ26: 40.966013 | CA26: 31.093627 | CB26: 31.353247 | CC26: 29.03934 | CD26: 64.615929 | CE26: 38.43109 | CF26: 53.284931 | CG26: 92.759735 | CH26: 63.836568 | CI26: 63.608659 | CJ26: 62.56472 | CK26: 71.347189 | CL26: 38.873669 | CM26: 76.797941 | CN26: 89.903081 | CO26: 99.399499 | CP26: 66.666319 | CQ26: 76.477056 | CR26: 89.835528 | CS26: 86.489739 | CT26: 30.07481 | CU26: 61.053672 | CV26: 38.391809 | CW26: 76.584208 | CX26: 41.478213 | CY26: 25.519086 | CZ26: 86.352193 | DA26: 25.814181 | DB26: 82.770244 | DC26: 88.902701 | DD26: 62.849927 | DE26: 49.212768 | DF26: 80.982709 | DG26: 89.298874 | DH26: 76.603988 | DI26: 57.812882 | DJ26: 54.369545 | DK26: 72.522673 | DL26: 91.387313 | DM26: 94.34808 | DN26: 75.32872 | DO26: 61.590533 | DP26: 99.6427 | DQ26: 65.027677 | DR26: 37.907065 | DS26: 39.525505 | DT26: 82.183479 | DU26: 98.105068 | DV26: 44.849063 | DW26: 51.008419 | DX26: 52.524385 | DY26: 86.484672 | DZ26: 76.226972 | EA26: 60.369899 | EB26: 79.338851 | EC26: 40.556774 | ED26: 40.006142 | EE26: 65.808272 | EF26: 44.556401 | EG26: 31.543556 | EH26: 42.77288 | EI26: 61.740802 | EJ26: 32.474627 | EK26: 70.649437 | EL26: 61.142257 | EM26: 29.112545 | EN26: 28.792697 | EO26: 65.961412 | EP26: 46.213953 | EQ26: 89.874837 | ER26: 92.000964 | ES26: 90.015899 | ET26: 99.865155 | EU26: 49.693905 | EV26: 68.017457 | EW26: 56.927484 | EX26: 94.067274 | EY26: 31.496048 | EZ26: 32.350435 | FA26: 95.86761 | FB26: 88.14795 | FC26: 81.179839 | FD26: 50.827843 | FE26: 33.579834 | FF26: 40.799418 | FG26: 85.095068 | FH26: 88.757737 | FI26: 32.040163 | FJ26: 71.762632 | FK26: 89.603477 | FL26: 60.765488 | FM26: 96.780579 | FN26: 67.445325 | FO26: 58.536753 | FP26: 85.726749 | FQ26: 96.097587 | FR26: 67.763909 | FS26: 79.819096 | FT26: 69.329578 | FU26: 93.662717 | FV26: 86.4452 | FW26: 53.983094 | FX26: 82.902259 | FY26: 57.388667 | FZ26: 40.461104 | GA26: 28.590955 | GB26: 26.189715 | GC26: 28.138762 | GD26: 86.566888 | GE26: 35.638775 | GF26: 69.607391 | GG26: 38.960087 | GH26: 51.331795 | GI26: 53.847541 | GJ26: 39.83709 | GK26: 79.415026 | GL26: 99.702032 | GM26: 73.415377 | GN26: 82.760584 | GO26: 41.657847 | GP26: 51.877893 | GQ26: 43.595592 | GR26: 51.101118 | GS26: 71.832679 | GT26: 45.956013 | GU26: 64.73087 | GV26: 34.100566 | GW26: 33.211781 | GX26: 46.349875 | GY26: 86.250661 | GZ26: 26.789723 | HA26: 82.862563 | HB26: 87.700206 | HC26: 77.664681 | HD26: 91.142253 | HE26: 78.450715 | HF26: 39.559559 | HG26: 79.271386 | HH26: 35.409256 | HI26: 93.405415 | HJ26: 85.33415 | HK26: 79.543604 | HL26: 79.848819 | HM26: 36.799473 | HN26: 86.051387 | HO26: 44.657523 | HP26: 29.685901 | HQ26: 93.760313 | HR26: 35.073019 | HS26: 98.404983 | HT26: 93.192137 | HU26: 66.971035 | HV26: 95.059449 | HW26: 29.619095 | HX26: 35.250953 | HY26: 58.982214 | HZ26: 43.363037 | IA26: 96.082357 | IB26: 56.714996 | IC26: 86.146774 | ID26: 48.200031 | IE26: 88.048431 | IF26: 72.480213 | IG26: 72.021685 | IH26: 44.927845 | II26: 70.956877 | IJ26: 75.235536 | IK26: 75.485499 | IL26: 91.928441 | IM26: 67.749736 | IN26: 50.85645 | IO26: 61.677234 | IP26: 51.723382 | IQ26: 57.350983 | IR26: 39.236485 | IS26: 65.320543 | IT26: 99.626969 | IU26: 56.203324 | IV26: 86.197107 | IW26: 60.262539 | IX26: 62.805097 | IY26: 30.982835 | IZ26: 85.040176 | JA26: 46.002324 | JB26: 46.681628 | JC26: 49.334346 | JD26: 99.420304 | JE26: 35.021947 | JF26: 87.747193 | JG26: 38.818884 | JH26: 33.721978 | JI26: 70.087283 | JJ26: 93.704641 | JK26: 30.170418 | JL26: 68.092881 | JM26: 25.537814 | JN26: 55.841261 | JO26: 90.965022 | JP26: 37.170169 | JQ26: 89.024833 | JR26: 87.380124 | JS26: 37.738203 | JT26: 88.817531 | JU26: 26.707503 | JV26: 88.610376 | JW26: 57.743227 | JX26: 33.042796 | JY26: 34.901572 | JZ26: 92.783007 | KA26: 95.375749 | KB26: 52.786535 | KC26: 85.086544 | KD26: 66.380424 | KE26: 44.464776 | KF26: 53.663819
E27: M Ltrs | J27: Lender case | K27: 55 | L27: 55 | M27: 55 | N27: 55 | O27: 55 | P27: 55 | Q27: 55 | R27: 55 | S27: 55 | T27: 55 | U27: 55 | V27: 55 | W27: 55 | X27: 55 | Y27: 55 | Z27: 55 | AA27: 55 | AB27: 55 | AC27: 55 | AD27: 55 | AE27: 55 | AF27: 55 | AG27: 55 | AH27: 55 | AI27: 55 | AJ27: 55 | AK27: 55 | AL27: 55 | AM27: 55 | AN27: 55 | AO27: 55 | AP27: 55 | AQ27: 55 | AR27: 55 | AS27: 55 | AT27: 55 | AU27: 55 | AV27: 55 | AW27: 55 | AX27: 55 | AY27: 55 | AZ27: 55 | BA27: 55 | BB27: 55 | BC27: 55 | BD27: 55 | BE27: 55 | BF27: 55 | BG27: 55 | BH27: 55 | BI27: 55 | BJ27: 55 | BK27: 55 | BL27: 55 | BM27: 55 | BN27: 55 | BO27: 55 | BP27: 55 | BQ27: 55 | BR27: 55 | BS27: 55 | BT27: 55 | BU27: 55 | BV27: 55 | BW27: 55 | BX27: 55 | BY27: 55 | BZ27: 55 | CA27: 55 | CB27: 55 | CC27: 55 | CD27: 55 | CE27: 55 | CF27: 55 | CG27: 55 | CH27: 55 | CI27: 55 | CJ27: 55 | CK27: 55 | CL27: 55 | CM27: 55 | CN27: 55 | CO27: 55 | CP27: 55 | CQ27: 55 | CR27: 55 | CS27: 55 | CT27: 55 | CU27: 55 | CV27: 55 | CW27: 55 | CX27: 55 | CY27: 55 | CZ27: 55 | DA27: 55 | DB27: 55 | DC27: 55 | DD27: 55 | DE27: 55 | DF27: 55 | DG27: 55 | DH27: 55 | DI27: 55 | DJ27: 55 | DK27: 55 | DL27: 55 | DM27: 55 | DN27: 55 | DO27: 55 | DP27: 55 | DQ27: 55 | DR27: 55 | DS27: 55 | DT27: 55 | DU27: 55 | DV27: 55 | DW27: 55 | DX27: 55 | DY27: 55 | DZ27: 55 | EA27: 55 | EB27: 55 | EC27: 55 | ED27: 55 | EE27: 55 | EF27: 55 | EG27: 55 | EH27: 55 | EI27: 55 | EJ27: 55 | EK27: 55 | EL27: 55 | EM27: 55 | EN27: 55 | EO27: 55 | EP27: 55 | EQ27: 55 | ER27: 55 | ES27: 55 | ET27: 55 | EU27: 55 | EV27: 55 | EW27: 55 | EX27: 55 | EY27: 55 | EZ27: 55 | FA27: 55 | FB27: 55 | FC27: 55 | FD27: 55 | FE27: 55 | FF27: 55 | FG27: 55 | FH27: 55 | FI27: 55 | FJ27: 55 | FK27: 55 | FL27: 55 | FM27: 55 | FN27: 55 | FO27: 55 | FP27: 55 | FQ27: 55 | FR27: 55 | FS27: 55 | FT27: 55 | FU27: 55 | FV27: 55 | FW27: 55 | FX27: 55 | FY27: 55 | FZ27: 55 | GA27: 55 | GB27: 55 | GC27: 55 | GD27: 55 | GE27: 55 | GF27: 55 | GG27: 55 | GH27: 55 | GI27: 55 | GJ27: 55 | GK27: 55 | GL27: 55 | GM27: 55 | GN27: 55 | GO27: 55 | GP27: 55 | GQ27: 55 | GR27: 55 | GS27: 55 | GT27: 55 | GU27: 55 | GV27: 55 | GW27: 55 | GX27: 55 | GY27: 55 | GZ27: 55 | HA27: 55 | HB27: 55 | HC27: 55 | HD27: 55 | HE27: 55 | HF27: 55 | HG27: 55 | HH27: 55 | HI27: 55 | HJ27: 55 | HK27: 55 | HL27: 55 | HM27: 55 | HN27: 55 | HO27: 55 | HP27: 55 | HQ27: 55 | HR27: 55 | HS27: 55 | HT27: 55 | HU27: 55 | HV27: 55 | HW27: 55 | HX27: 55 | HY27: 55 | HZ27: 55 | IA27: 55 | IB27: 55 | IC27: 55 | ID27: 55 | IE27: 55 | IF27: 55 | IG27: 55 | IH27: 55 | II27: 55 | IJ27: 55 | IK27: 55 | IL27: 55 | IM27: 55 | IN27: 55 | IO27: 55 | IP27: 55 | IQ27: 55 | IR27: 55 | IS27: 55 | IT27: 55 | IU27: 55 | IV27: 55 | IW27: 55 | IX27: 55 | IY27: 55 | IZ27: 55 | JA27: 55 | JB27: 55 | JC27: 55 | JD27: 55 | JE27: 55 | JF27: 55 | JG27: 55 | JH27: 55 | JI27: 55 | JJ27: 55 | JK27: 55 | JL27: 55 | JM27: 55 | JN27: 55 | JO27: 55 | JP27: 55 | JQ27: 55 | JR27: 55 | JS27: 55 | JT27: 55 | JU27: 55 | JV27: 55 | JW27: 55 | JX27: 55 | JY27: 55 | JZ27: 55 | KA27: 55 | KB27: 55 | KC27: 55 | KD27: 55 | KE27: 55 | KF27: 55
E28: M Ltrs | J28: Downside case | K28: 40 | L28: 40 | M28: 40 | N28: 40 | O28: 40 | P28: 40 | Q28: 40 | R28: 40 | S28: 40 | T28: 40 | U28: 40 | V28: 40 | W28: 40 | X28: 40 | Y28: 40 | Z28: 40 | AA28: 40 | AB28: 40 | AC28: 40 | AD28: 40 | AE28: 40 | AF28: 40 | AG28: 40 | AH28: 40 | AI28: 40 | AJ28: 40 | AK28: 40 | AL28: 40 | AM28: 40 | AN28: 40 | AO28: 40 | AP28: 40 | AQ28: 40 | AR28: 40 | AS28: 40 | AT28: 40 | AU28: 40 | AV28: 40 | AW28: 40 | AX28: 40 | AY28: 40 | AZ28: 40 | BA28: 40 | BB28: 40 | BC28: 40 | BD28: 40 | BE28: 40 | BF28: 40 | BG28: 40 | BH28: 40 | BI28: 40 | BJ28: 40 | BK28: 40 | BL28: 40 | BM28: 40 | BN28: 40 | BO28: 40 | BP28: 40 | BQ28: 40 | BR28: 40 | BS28: 40 | BT28: 40 | BU28: 40 | BV28: 40 | BW28: 40 | BX28: 40 | BY28: 40 | BZ28: 40 | CA28: 40 | CB28: 40 | CC28: 40 | CD28: 40 | CE28: 40 | CF28: 40 | CG28: 40 | CH28: 40 | CI28: 40 | CJ28: 40 | CK28: 40 | CL28: 40 | CM28: 40 | CN28: 40 | CO28: 40 | CP28: 40 | CQ28: 40 | CR28: 40 | CS28: 40 | CT28: 40 | CU28: 40 | CV28: 40 | CW28: 40 | CX28: 40 | CY28: 40 | CZ28: 40 | DA28: 40 | DB28: 40 | DC28: 40 | DD28: 40 | DE28: 40 | DF28: 40 | DG28: 40 | DH28: 40 | DI28: 40 | DJ28: 40 | DK28: 40 | DL28: 40 | DM28: 40 | DN28: 40 | DO28: 40 | DP28: 40 | DQ28: 40 | DR28: 40 | DS28: 40 | DT28: 40 | DU28: 40 | DV28: 40 | DW28: 40 | DX28: 40 | DY28: 40 | DZ28: 40 | EA28: 40 | EB28: 40 | EC28: 40 | ED28: 40 | EE28: 40 | EF28: 40 | EG28: 40 | EH28: 40 | EI28: 40 | EJ28: 40 | EK28: 40 | EL28: 40 | EM28: 40 | EN28: 40 | EO28: 40 | EP28: 40 | EQ28: 40 | ER28: 40 | ES28: 40 | ET28: 40 | EU28: 40 | EV28: 40 | EW28: 40 | EX28: 40 | EY28: 40 | EZ28: 40 | FA28: 40 | FB28: 40 | FC28: 40 | FD28: 40 | FE28: 40 | FF28: 40 | FG28: 40 | FH28: 40 | FI28: 40 | FJ28: 40 | FK28: 40 | FL28: 40 | FM28: 40 | FN28: 40 | FO28: 40 | FP28: 40 | FQ28: 40 | FR28: 40 | FS28: 40 | FT28: 40 | FU28: 40 | FV28: 40 | FW28: 40 | FX28: 40 | FY28: 40 | FZ28: 40 | GA28: 40 | GB28: 40 | GC28: 40 | GD28: 40 | GE28: 40 | GF28: 40 | GG28: 40 | GH28: 40 | GI28: 40 | GJ28: 40 | GK28: 40 | GL28: 40 | GM28: 40 | GN28: 40 | GO28: 40 | GP28: 40 | GQ28: 40 | GR28: 40 | GS28: 40 | GT28: 40 | GU28: 40 | GV28: 40 | GW28: 40 | GX28: 40 | GY28: 40 | GZ28: 40 | HA28: 40 | HB28: 40 | HC28: 40 | HD28: 40 | HE28: 40 | HF28: 40 | HG28: 40 | HH28: 40 | HI28: 40 | HJ28: 40 | HK28: 40 | HL28: 40 | HM28: 40 | HN28: 40 | HO28: 40 | HP28: 40 | HQ28: 40 | HR28: 40 | HS28: 40 | HT28: 40 | HU28: 40 | HV28: 40 | HW28: 40 | HX28: 40 | HY28: 40 | HZ28: 40 | IA28: 40 | IB28: 40 | IC28: 40 | ID28: 40 | IE28: 40 | IF28: 40 | IG28: 40 | IH28: 40 | II28: 40 | IJ28: 40 | IK28: 40 | IL28: 40 | IM28: 40 | IN28: 40 | IO28: 40 | IP28: 40 | IQ28: 40 | IR28: 40 | IS28: 40 | IT28: 40 | IU28: 40 | IV28: 40 | IW28: 40 | IX28: 40 | IY28: 40 | IZ28: 40 | JA28: 40 | JB28: 40 | JC28: 40 | JD28: 40 | JE28: 40 | JF28: 40 | JG28: 40 | JH28: 40 | JI28: 40 | JJ28: 40 | JK28: 40 | JL28: 40 | JM28: 40 | JN28: 40 | JO28: 40 | JP28: 40 | JQ28: 40 | JR28: 40 | JS28: 40 | JT28: 40 | JU28: 40 | JV28: 40 | JW28: 40 | JX28: 40 | JY28: 40 | JZ28: 40 | KA28: 40 | KB28: 40 | KC28: 40 | KD28: 40 | KE28: 40 | KF28: 40
E29: M Ltrs | J29: [Spare]
E30: M Ltrs | J30: [Spare]
E31: M Ltrs | J31: [Spare]
E32: M Ltrs | J32: [Spare]
E33: M Ltrs | J33: [Spare]
E34: M Ltrs | J34: [Spare]
H36: Sales Price
J38: Chosen case | K38: =Control!H18 -> 1 | L38: {=INDEX(J42:J50,K38)} -> Base case
E39: USD/Ltr, real | J39: Live Price | K39: {=INDEX(K42:K50,$K$38)} -> 2.35 | L39: {=INDEX(L42:L50,$K$38)} -> 2.35 | M39: {=INDEX(M42:M50,$K$38)} -> 2.35 | N39: {=INDEX(N42:N50,$K$38)} -> 2.35 | O39: {=INDEX(O42:O50,$K$38)} -> 2.35 | P39: {=INDEX(P42:P50,$K$38)} -> 2.35 | Q39: {=INDEX(Q42:Q50,$K$38)} -> 2.3 | R39: {=INDEX(R42:R50,$K$38)} -> 2.3 | ... KF39: {=INDEX(KF42:KF50,$K$38)} -> 2.25
D40: 0 | E40: USD/Ltr, real | J40: Bank Adjustment | K40: =K39*(1+$D40) -> 2.35 | L40: =L39*(1+$D40) -> 2.35 | M40: =M39*(1+$D40) -> 2.35 | N40: =N39*(1+$D40) -> 2.35 | O40: =O39*(1+$D40) -> 2.35 | P40: =P39*(1+$D40) -> 2.35 | Q40: =Q39*(1+$D40) -> 2.3 | R40: =R39*(1+$D40) -> 2.3 | ... KF40: =KF39*(1+$D40) -> 2.25
E42: USD/Ltr, real | J42: Base case | K42: 2.35 | L42: 2.35 | M42: 2.35 | N42: 2.35 | O42: 2.35 | P42: 2.35 | Q42: 2.3 | R42: 2.3 | S42: 2.3 | T42: 2.3 | U42: 2.3 | V42: 2.3 | W42: 2.3 | X42: 2.3 | Y42: 2.25 | Z42: 2.25 | AA42: 2.25 | AB42: 2.25 | AC42: 2.25 | AD42: 2.25 | AE42: 2.25 | AF42: 2.25 | AG42: 2.25 | AH42: 2.25 | AI42: 2.25 | AJ42: 2.25 | AK42: 2.25 | AL42: 2.25 | AM42: 2.25 | AN42: 2.25 | AO42: 2.25 | AP42: 2.25 | AQ42: 2.25 | AR42: 2.25 | AS42: 2.25 | AT42: 2.25 | AU42: 2.25 | AV42: 2.25 | AW42: 2.25 | AX42: 2.25 | AY42: 2.25 | AZ42: 2.25 | BA42: 2.25 | BB42: 2.25 | BC42: 2.25 | BD42: 2.25 | BE42: 2.25 | BF42: 2.25 | BG42: 2.25 | BH42: 2.25 | BI42: 2.25 | BJ42: 2.25 | BK42: 2.25 | BL42: 2.25 | BM42: 2.25 | BN42: 2.25 | BO42: 2.25 | BP42: 2.25 | BQ42: 2.25 | BR42: 2.25 | BS42: 2.25 | BT42: 2.25 | BU42: 2.25 | BV42: 2.25 | BW42: 2.25 | BX42: 2.25 | BY42: 2.25 | BZ42: 2.25 | CA42: 2.25 | CB42: 2.25 | CC42: 2.25 | CD42: 2.25 | CE42: 2.25 | CF42: 2.25 | CG42: 2.25 | CH42: 2.25 | CI42: 2.25 | CJ42: 2.25 | CK42: 2.25 | CL42: 2.25 | CM42: 2.25 | CN42: 2.25 | CO42: 2.25 | CP42: 2.25 | CQ42: 2.25 | CR42: 2.25 | CS42: 2.25 | CT42: 2.25 | CU42: 2.25 | CV42: 2.25 | CW42: 2.25 | CX42: 2.25 | CY42: 2.25 | CZ42: 2.25 | DA42: 2.25 | DB42: 2.25 | DC42: 2.25 | DD42: 2.25 | DE42: 2.25 | DF42: 2.25 | DG42: 2.25 | DH42: 2.25 | DI42: 2.25 | DJ42: 2.25 | DK42: 2.25 | DL42: 2.25 | DM42: 2.25 | DN42: 2.25 | DO42: 2.25 | DP42: 2.25 | DQ42: 2.25 | DR42: 2.25 | DS42: 2.25 | DT42: 2.25 | DU42: 2.25 | DV42: 2.25 | DW42: 2.25 | DX42: 2.25 | DY42: 2.25 | DZ42: 2.25 | EA42: 2.25 | EB42: 2.25 | EC42: 2.25 | ED42: 2.25 | EE42: 2.25 | EF42: 2.25 | EG42: 2.25 | EH42: 2.25 | EI42: 2.25 | EJ42: 2.25 | EK42: 2.25 | EL42: 2.25 | EM42: 2.25 | EN42: 2.25 | EO42: 2.25 | EP42: 2.25 | EQ42: 2.25 | ER42: 2.25 | ES42: 2.25 | ET42: 2.25 | EU42: 2.25 | EV42: 2.25 | EW42: 2.25 | EX42: 2.25 | EY42: 2.25 | EZ42: 2.25 | FA42: 2.25 | FB42: 2.25 | FC42: 2.25 | FD42: 2.25 | FE42: 2.25 | FF42: 2.25 | FG42: 2.25 | FH42: 2.25 | FI42: 2.25 | FJ42: 2.25 | FK42: 2.25 | FL42: 2.25 | FM42: 2.25 | FN42: 2.25 | FO42: 2.25 | FP42: 2.25 | FQ42: 2.25 | FR42: 2.25 | FS42: 2.25 | FT42: 2.25 | FU42: 2.25 | FV42: 2.25 | FW42: 2.25 | FX42: 2.25 | FY42: 2.25 | FZ42: 2.25 | GA42: 2.25 | GB42: 2.25 | GC42: 2.25 | GD42: 2.25 | GE42: 2.25 | GF42: 2.25 | GG42: 2.25 | GH42: 2.25 | GI42: 2.25 | GJ42: 2.25 | GK42: 2.25 | GL42: 2.25 | GM42: 2.25 | GN42: 2.25 | GO42: 2.25 | GP42: 2.25 | GQ42: 2.25 | GR42: 2.25 | GS42: 2.25 | GT42: 2.25 | GU42: 2.25 | GV42: 2.25 | GW42: 2.25 | GX42: 2.25 | GY42: 2.25 | GZ42: 2.25 | HA42: 2.25 | HB42: 2.25 | HC42: 2.25 | HD42: 2.25 | HE42: 2.25 | HF42: 2.25 | HG42: 2.25 | HH42: 2.25 | HI42: 2.25 | HJ42: 2.25 | HK42: 2.25 | HL42: 2.25 | HM42: 2.25 | HN42: 2.25 | HO42: 2.25 | HP42: 2.25 | HQ42: 2.25 | HR42: 2.25 | HS42: 2.25 | HT42: 2.25 | HU42: 2.25 | HV42: 2.25 | HW42: 2.25 | HX42: 2.25 | HY42: 2.25 | HZ42: 2.25 | IA42: 2.25 | IB42: 2.25 | IC42: 2.25 | ID42: 2.25 | IE42: 2.25 | IF42: 2.25 | IG42: 2.25 | IH42: 2.25 | II42: 2.25 | IJ42: 2.25 | IK42: 2.25 | IL42: 2.25 | IM42: 2.25 | IN42: 2.25 | IO42: 2.25 | IP42: 2.25 | IQ42: 2.25 | IR42: 2.25 | IS42: 2.25 | IT42: 2.25 | IU42: 2.25 | IV42: 2.25 | IW42: 2.25 | IX42: 2.25 | IY42: 2.25 | IZ42: 2.25 | JA42: 2.25 | JB42: 2.25 | JC42: 2.25 | JD42: 2.25 | JE42: 2.25 | JF42: 2.25 | JG42: 2.25 | JH42: 2.25 | JI42: 2.25 | JJ42: 2.25 | JK42: 2.25 | JL42: 2.25 | JM42: 2.25 | JN42: 2.25 | JO42: 2.25 | JP42: 2.25 | JQ42: 2.25 | JR42: 2.25 | JS42: 2.25 | JT42: 2.25 | JU42: 2.25 | JV42: 2.25 | JW42: 2.25 | JX42: 2.25 | JY42: 2.25 | JZ42: 2.25 | KA42: 2.25 | KB42: 2.25 | KC42: 2.25 | KD42: 2.25 | KE42: 2.25 | KF42: 2.25
E43: USD/Ltr, real | J43: Lender case | K43: 2.3 | L43: 2.3 | M43: 2.3 | N43: 2.3 | O43: 2.3 | P43: 2.3 | Q43: 2.05 | R43: 2.05 | S43: 2.05 | T43: 2.05 | U43: 2.05 | V43: 2.05 | W43: 2.05 | X43: 2.05 | Y43: 2.05 | Z43: 2.05 | AA43: 2.05 | AB43: 2.05 | AC43: 2.05 | AD43: 2.05 | AE43: 2.05 | AF43: 2.05 | AG43: 2.05 | AH43: 2.05 | AI43: 2.05 | AJ43: 2.05 | AK43: 2.05 | AL43: 2.05 | AM43: 2.05 | AN43: 2.05 | AO43: 2.05 | AP43: 2.05 | AQ43: 2.05 | AR43: 2.05 | AS43: 2.05 | AT43: 2.05 | AU43: 2.05 | AV43: 2.05 | AW43: 2.05 | AX43: 2.05 | AY43: 2.05 | AZ43: 2.05 | BA43: 2.05 | BB43: 2.05 | BC43: 2.05 | BD43: 2.05 | BE43: 2.05 | BF43: 2.05 | BG43: 2.05 | BH43: 2.05 | BI43: 2.05 | BJ43: 2.05 | BK43: 2.05 | BL43: 2.05 | BM43: 2.05 | BN43: 2.05 | BO43: 2.05 | BP43: 2.05 | BQ43: 2.05 | BR43: 2.05 | BS43: 2.05 | BT43: 2.05 | BU43: 2.05 | BV43: 2.05 | BW43: 2.05 | BX43: 2.05 | BY43: 2.05 | BZ43: 2.05 | CA43: 2.05 | CB43: 2.05 | CC43: 2.05 | CD43: 2.05 | CE43: 2.05 | CF43: 2.05 | CG43: 2.05 | CH43: 2.05 | CI43: 2.05 | CJ43: 2.05 | CK43: 2.05 | CL43: 2.05 | CM43: 2.05 | CN43: 2.05 | CO43: 2.05 | CP43: 2.05 | CQ43: 2.05 | CR43: 2.05 | CS43: 2.05 | CT43: 2.05 | CU43: 2.05 | CV43: 2.05 | CW43: 2.05 | CX43: 2.05 | CY43: 2.05 | CZ43: 2.05 | DA43: 2.05 | DB43: 2.05 | DC43: 2.05 | DD43: 2.05 | DE43: 2.05 | DF43: 2.05 | DG43: 2.05 | DH43: 2.05 | DI43: 2.05 | DJ43: 2.05 | DK43: 2.05 | DL43: 2.05 | DM43: 2.05 | DN43: 2.05 | DO43: 2.05 | DP43: 2.05 | DQ43: 2.05 | DR43: 2.05 | DS43: 2.05 | DT43: 2.05 | DU43: 2.05 | DV43: 2.05 | DW43: 2.05 | DX43: 2.05 | DY43: 2.05 | DZ43: 2.05 | EA43: 2.05 | EB43: 2.05 | EC43: 2.05 | ED43: 2.05 | EE43: 2.05 | EF43: 2.05 | EG43: 2.05 | EH43: 2.05 | EI43: 2.05 | EJ43: 2.05 | EK43: 2.05 | EL43: 2.05 | EM43: 2.05 | EN43: 2.05 | EO43: 2.05 | EP43: 2.05 | EQ43: 2.05 | ER43: 2.05 | ES43: 2.05 | ET43: 2.05 | EU43: 2.05 | EV43: 2.05 | EW43: 2.05 | EX43: 2.05 | EY43: 2.05 | EZ43: 2.05 | FA43: 2.05 | FB43: 2.05 | FC43: 2.05 | FD43: 2.05 | FE43: 2.05 | FF43: 2.05 | FG43: 2.05 | FH43: 2.05 | FI43: 2.05 | FJ43: 2.05 | FK43: 2.05 | FL43: 2.05 | FM43: 2.05 | FN43: 2.05 | FO43: 2.05 | FP43: 2.05 | FQ43: 2.05 | FR43: 2.05 | FS43: 2.05 | FT43: 2.05 | FU43: 2.05 | FV43: 2.05 | FW43: 2.05 | FX43: 2.05 | FY43: 2.05 | FZ43: 2.05 | GA43: 2.05 | GB43: 2.05 | GC43: 2.05 | GD43: 2.05 | GE43: 2.05 | GF43: 2.05 | GG43: 2.05 | GH43: 2.05 | GI43: 2.05 | GJ43: 2.05 | GK43: 2.05 | GL43: 2.05 | GM43: 2.05 | GN43: 2.05 | GO43: 2.05 | GP43: 2.05 | GQ43: 2.05 | GR43: 2.05 | GS43: 2.05 | GT43: 2.05 | GU43: 2.05 | GV43: 2.05 | GW43: 2.05 | GX43: 2.05 | GY43: 2.05 | GZ43: 2.05 | HA43: 2.05 | HB43: 2.05 | HC43: 2.05 | HD43: 2.05 | HE43: 2.05 | HF43: 2.05 | HG43: 2.05 | HH43: 2.05 | HI43: 2.05 | HJ43: 2.05 | HK43: 2.05 | HL43: 2.05 | HM43: 2.05 | HN43: 2.05 | HO43: 2.05 | HP43: 2.05 | HQ43: 2.05 | HR43: 2.05 | HS43: 2.05 | HT43: 2.05 | HU43: 2.05 | HV43: 2.05 | HW43: 2.05 | HX43: 2.05 | HY43: 2.05 | HZ43: 2.05 | IA43: 2.05 | IB43: 2.05 | IC43: 2.05 | ID43: 2.05 | IE43: 2.05 | IF43: 2.05 | IG43: 2.05 | IH43: 2.05 | II43: 2.05 | IJ43: 2.05 | IK43: 2.05 | IL43: 2.05 | IM43: 2.05 | IN43: 2.05 | IO43: 2.05 | IP43: 2.05 | IQ43: 2.05 | IR43: 2.05 | IS43: 2.05 | IT43: 2.05 | IU43: 2.05 | IV43: 2.05 | IW43: 2.05 | IX43: 2.05 | IY43: 2.05 | IZ43: 2.05 | JA43: 2.05 | JB43: 2.05 | JC43: 2.05 | JD43: 2.05 | JE43: 2.05 | JF43: 2.05 | JG43: 2.05 | JH43: 2.05 | JI43: 2.05 | JJ43: 2.05 | JK43: 2.05 | JL43: 2.05 | JM43: 2.05 | JN43: 2.05 | JO43: 2.05 | JP43: 2.05 | JQ43: 2.05 | JR43: 2.05 | JS43: 2.05 | JT43: 2.05 | JU43: 2.05 | JV43: 2.05 | JW43: 2.05 | JX43: 2.05 | JY43: 2.05 | JZ43: 2.05 | KA43: 2.05 | KB43: 2.05 | KC43: 2.05 | KD43: 2.05 | KE43: 2.05 | KF43: 2.05
E44: USD/Ltr, real | J44: Downside case | K44: 2.35 | L44: 2.32 | M44: 2.29 | N44: 2.26 | O44: 2.23 | P44: 2.2 | Q44: 2.17 | R44: 2.14 | S44: 2.11 | T44: 2.08 | U44: 2.05 | V44: 2.02 | W44: 2 | X44: 2 | Y44: 2 | Z44: 2 | AA44: 2 | AB44: 2 | AC44: 2 | AD44: 2 | AE44: 2 | AF44: 2 | AG44: 2 | AH44: 2 | AI44: 2 | AJ44: 2 | AK44: 2 | AL44: 2 | AM44: 2 | AN44: 2 | AO44: 2 | AP44: 2 | AQ44: 2 | AR44: 2 | AS44: 2 | AT44: 2 | AU44: 2 | AV44: 2 | AW44: 2 | AX44: 2 | AY44: 2 | AZ44: 2 | BA44: 2 | BB44: 2 | BC44: 2 | BD44: 2 | BE44: 2 | BF44: 2 | BG44: 2 | BH44: 2 | BI44: 2 | BJ44: 2 | BK44: 2 | BL44: 2 | BM44: 2 | BN44: 2 | BO44: 2 | BP44: 2 | BQ44: 2 | BR44: 2 | BS44: 2 | BT44: 2 | BU44: 2 | BV44: 2 | BW44: 2 | BX44: 2 | BY44: 2 | BZ44: 2 | CA44: 2 | CB44: 2 | CC44: 2 | CD44: 2 | CE44: 2 | CF44: 2 | CG44: 2 | CH44: 2 | CI44: 2 | CJ44: 2 | CK44: 2 | CL44: 2 | CM44: 2 | CN44: 2 | CO44: 2 | CP44: 2 | CQ44: 2 | CR44: 2 | CS44: 2 | CT44: 2 | CU44: 2 | CV44: 2 | CW44: 2 | CX44: 2 | CY44: 2 | CZ44: 2 | DA44: 2 | DB44: 2 | DC44: 2 | DD44: 2 | DE44: 2 | DF44: 2 | DG44: 2 | DH44: 2 | DI44: 2 | DJ44: 2 | DK44: 2 | DL44: 2 | DM44: 2 | DN44: 2 | DO44: 2 | DP44: 2 | DQ44: 2 | DR44: 2 | DS44: 2 | DT44: 2 | DU44: 2 | DV44: 2 | DW44: 2 | DX44: 2 | DY44: 2 | DZ44: 2 | EA44: 2 | EB44: 2 | EC44: 2 | ED44: 2 | EE44: 2 | EF44: 2 | EG44: 2 | EH44: 2 | EI44: 2 | EJ44: 2 | EK44: 2 | EL44: 2 | EM44: 2 | EN44: 2 | EO44: 2 | EP44: 2 | EQ44: 2 | ER44: 2 | ES44: 2 | ET44: 2 | EU44: 2 | EV44: 2 | EW44: 2 | EX44: 2 | EY44: 2 | EZ44: 2 | FA44: 2 | FB44: 2 | FC44: 2 | FD44: 2 | FE44: 2 | FF44: 2 | FG44: 2 | FH44: 2 | FI44: 2 | FJ44: 2 | FK44: 2 | FL44: 2 | FM44: 2 | FN44: 2 | FO44: 2 | FP44: 2 | FQ44: 2 | FR44: 2 | FS44: 2 | FT44: 2 | FU44: 2 | FV44: 2 | FW44: 2 | FX44: 2 | FY44: 2 | FZ44: 2 | GA44: 2 | GB44: 2 | GC44: 2 | GD44: 2 | GE44: 2 | GF44: 2 | GG44: 2 | GH44: 2 | GI44: 2 | GJ44: 2 | GK44: 2 | GL44: 2 | GM44: 2 | GN44: 2 | GO44: 2 | GP44: 2 | GQ44: 2 | GR44: 2 | GS44: 2 | GT44: 2 | GU44: 2 | GV44: 2 | GW44: 2 | GX44: 2 | GY44: 2 | GZ44: 2 | HA44: 2 | HB44: 2 | HC44: 2 | HD44: 2 | HE44: 2 | HF44: 2 | HG44: 2 | HH44: 2 | HI44: 2 | HJ44: 2 | HK44: 2 | HL44: 2 | HM44: 2 | HN44: 2 | HO44: 2 | HP44: 2 | HQ44: 2 | HR44: 2 | HS44: 2 | HT44: 2 | HU44: 2 | HV44: 2 | HW44: 2 | HX44: 2 | HY44: 2 | HZ44: 2 | IA44: 2 | IB44: 2 | IC44: 2 | ID44: 2 | IE44: 2 | IF44: 2 | IG44: 2 | IH44: 2 | II44: 2 | IJ44: 2 | IK44: 2 | IL44: 2 | IM44: 2 | IN44: 2 | IO44: 2 | IP44: 2 | IQ44: 2 | IR44: 2 | IS44: 2 | IT44: 2 | IU44: 2 | IV44: 2 | IW44: 2 | IX44: 2 | IY44: 2 | IZ44: 2 | JA44: 2 | JB44: 2 | JC44: 2 | JD44: 2 | JE44: 2 | JF44: 2 | JG44: 2 | JH44: 2 | JI44: 2 | JJ44: 2 | JK44: 2 | JL44: 2 | JM44: 2 | JN44: 2 | JO44: 2 | JP44: 2 | JQ44: 2 | JR44: 2 | JS44: 2 | JT44: 2 | JU44: 2 | JV44: 2 | JW44: 2 | JX44: 2 | JY44: 2 | JZ44: 2 | KA44: 2 | KB44: 2 | KC44: 2 | KD44: 2 | KE44: 2 | KF44: 2
E45: USD/Ltr, real | J45: [Spare]
E46: USD/Ltr, real | J46: [Spare]
E47: USD/Ltr, real | J47: [Spare]
E48: USD/Ltr, real | J48: [Spare]
E49: USD/Ltr, real | J49: [Spare]
E50: USD/Ltr, real | J50: [Spare]
...

Sheet Control
B2: Metrics | D2: Basic Financial Model
D3: =MID(CELL("filename",A1),FIND("]",CELL("filename",A1))+1,255) -> Control
B4: Units | D4: ="Financial Scenario: "&H10 -> Financial Scenario: Base Case
D7: Scenario Selection | H7: LIVE
G9: Case Number | H9: 1 | J9: 1 | K9: 2 | L9: 3 | M9: 4 | N9: 5 | O9: 6 | P9: 7 | Q9: 8 | R9: 9
G10: Case Name | H10: {=INDEX(J10:R10,,$H$9)} -> Base Case | J10: Base Case | K10: Modelled | L10: [Spare 3] | M10: [Spare 4] | N10: [Spare 5] | O10: [Spare 6] | P10: [Spare 7] | Q10: [Spare 8] | R10: [Spare 9]
D12: Model Assumptions
E14: Model Input Assumptions
F16: Input Assumptions
G17: Sales Volume | H17: {=INDEX(J17:R17,,$H$9)} -> 1 | J17: 1 | K17: 2 | L17: 3 | M17: 3 | N17: 1 | O17: 1 | P17: 1 | Q17: 1 | R17: 1
G18: Sales Price | H18: {=INDEX(J18:R18,,$H$9)} -> 1 | J18: 1 | K18: 2 | L18: 3 | M18: 3 | N18: 1 | O18: 1 | P18: 1 | Q18: 1 | R18: 1
G19: Unit Cost | H19: {=INDEX(J19:R19,,$H$9)} -> 1 | J19: 1 | K19: 2 | L19: 3 | M19: 3 | N19: 1 | O19: 1 | P19: 1 | Q19: 1 | R19: 1
G20: Fixed Costs | H20: {=INDEX(J20:R20,,$H$9)} -> 1 | J20: 1 | K20: 2 | L20: 3 | M20: 3 | N20: 1 | O20: 1 | P20: 1 | Q20: 1 | R20: 1
G21: SG&A | H21: {=INDEX(J21:R21,,$H$9)} -> 1 | J21: 1 | K21: 2 | L21: 3 | M21: 4 | N21: 1 | O21: 1 | P21: 1 | Q21: 1 | R21: 1
G22: Other Costs | H22: {=INDEX(J22:R22,,$H$9)} -> 1 | J22: 1 | K22: 2 | L22: 3 | M22: 4 | N22: 1 | O22: 1 | P22: 1 | Q22: 1 | R22: 1
G23: Capex | H23: {=INDEX(J23:R23,,$H$9)} -> 1 | J23: 1 | K23: 2 | L23: 3 | M23: 4 | N23: 1 | O23: 1 | P23: 1 | Q23: 1 | R23: 1
G24: Tax | H24: {=INDEX(J24:R24,,$H$9)} -> 1 | J24: 1 | K24: 2 | L24: 3 | M24: 4 | N24: 1 | O24: 1 | P24: 1 | Q24: 1 | R24: 1
G25: SOFR | H25: {=INDEX(J25:R25,,$H$9)} -> 1 | J25: 1 | K25: 2 | L25: 3 | M25: 4 | N25: 1 | O25: 1 | P25: 1 | Q25: 1 | R25: 1
D27: Financing
E29: Credit Metrics
F31: Financial Covenants
B32: #x | G32: DSCR Covenant | H32: {=INDEX(J32:R32,,$H$9)} -> 1.25 | J32: 1.25 | K32: 1.25 | L32: 1.25 | M32: 1.25 | N32: 1.25 | O32: 1.25 | P32: 1.25 | Q32: 1.25 | R32: 1.25
B33: % | G33: Gearing Covenant | H33: {=INDEX(J33:R33,,$H$9)} -> 0.4 | J33: 0.4 | K33: 0.4 | L33: 0.4 | M33: 0.4 | N33: 0.4 | O33: 0.4 | P33: 0.4 | Q33: 0.4 | R33: 0.4
B34: USDm | G34: Min Cash Balance | H34: {=INDEX(J34:R34,,$H$9)} -> 100 | J34: 100 | K34: 100 | L34: 100 | M34: 100 | N34: 100 | O34: 100 | P34: 100 | Q34: 100 | R34: 100
E36: Facility
F38: Existing Term Loan
B39: Date | G39: Establishment Date | H39: {=INDEX(J39:R39,,$H$9)} -> 45565 | J39: =DATE(2024,9,30) -> 45565 | K39: =DATE(2024,9,30) -> 45565 | L39: =DATE(2024,9,30) -> 45565 | M39: =DATE(2024,9,30) -> 45565 | N39: =DATE(2024,9,30) -> 45565 | O39: =DATE(2024,9,30) -> 45565 | P39: =DATE(2024,9,30) -> 45565 | Q39: =DATE(2024,9,30) -> 45565 | R39: =DATE(2024,9,30) -> 45565
B40: USDm | G40: Facility Size | H40: {=INDEX(J40:R40,,$H$9)} -> 350 | J40: 350 | K40: 350 | L40: 350 | M40: 350 | N40: 350 | O40: 350 | P40: 350 | Q40: 350 | R40: 350
B41: Date | G41: Facility Maturity Date | H41: {=INDEX(J41:R41,,$H$9)} -> 47391 | J41: =DATE(2029,9,30) -> 47391 | K41: =DATE(2029,9,30) -> 47391 | L41: =DATE(2029,9,30) -> 47391 | M41: =DATE(2029,9,30) -> 47391 | N41: =DATE(2029,9,30) -> 47391 | O41: =DATE(2029,9,30) -> 47391 | P41: =DATE(2029,9,30) -> 47391 | Q41: =DATE(2029,9,30) -> 47391 | R41: =DATE(2029,9,30) -> 47391
B42: Text | G42: Reference Rate | H42: {=INDEX(J42:R42,,$H$9)} -> SOFR | J42: SOFR | K42: SOFR | L42: SOFR | M42: SOFR | N42: SOFR | O42: SOFR | P42: SOFR | Q42: SOFR | R42: SOFR
B43: Perc | G43: Margin | H43: {=INDEX(J43:R43,,$H$9)} -> 0.045 | J43: 0.045 | K43: 0.045 | L43: 0.045 | M43: 0.045 | N43: 0.045 | O43: 0.045 | P43: 0.045 | Q43: 0.045 | R43: 0.045
B44: USDm | G44: Balance at 30 June 2026 | H44: {=INDEX(J44:R44,,$H$9)} -> 245 | J44: 245 | K44: 245 | L44: 245 | M44: 245 | N44: 245 | O44: 245 | P44: 245 | Q44: 245 | R44: 245
B45: USDm | G45: Establishment Fee | H45: {=INDEX(J45:R45,,$H$9)} -> 7 | J45: 7 | K45: 7 | L45: 7 | M45: 7 | N45: 7 | O45: 7 | P45: 7 | Q45: 7 | R45: 7
B46: USDm | G46: Fee Amortisation Balance 30 June 2026 | H46: {=INDEX(J46:R46,,$H$9)} -> 2.5 | J46: 2.5 | K46: 2.5 | L46: 2.5 | M46: 2.5 | N46: 2.5 | O46: 2.5 | P46: 2.5 | Q46: 2.5 | R46: 2.5
B47: Years | G47: Facility Term | H47: =YEARFRAC(H39,H41) -> 5
B48: Months | G48: Facility Term - months | H48: =(YEAR(H41)-YEAR(H39))*12+MONTH(H39)-MONTH(H41) -> 60
G49: Monthly Fee Amortisation | H49: =H45/H48 -> 0.11666667
F51: Existing Term Loan - Amortisation Schedule
G52: Month | H52: Amount
B53: USDm | G53: 3 | H53: {=INDEX(J53:R53,,$H$9)} -> 35 | J53: 35 | K53: 35 | L53: 35 | M53: 35 | N53: 35 | O53: 35 | P53: 35 | Q53: 35 | R53: 35
...

Sheet TRAINING >>

Sheet Dates
B1: =Control!$D$2 -> Basic Financial Model
B2: =MID(CELL("filename",$B$1),FIND("]",CELL("filename",$B$1))+1,255) -> Dates
B3: =Control!$D$4 -> Financial Scenario: Base Case
B4: Calendar Year | F4: =F12 -> CY26 | G4: =G12 -> CY26 | H4: =H12 -> CY26 | I4: =I12 -> CY26 | J4: =J12 -> CY26 | K4: =K12 -> CY26 | L4: =L12 -> CY27 | M4: =M12 -> CY27 | ... KA4: =KA12 -> CY49
B5: Financial Year | F5: =F13 -> FY27 | G5: =G13 -> FY27 | H5: =H13 -> FY27 | I5: =I13 -> FY27 | J5: =J13 -> FY27 | K5: =K13 -> FY27 | L5: =L13 -> FY27 | M5: =M13 -> FY27 | ... KA5: =KA13 -> FY50
B6: Date | F6: =TEXT(F11,"mmm-yy") -> Jul-26 | G6: =TEXT(G11,"mmm-yy") -> Aug-26 | H6: =TEXT(H11,"mmm-yy") -> Sep-26 | I6: =TEXT(I11,"mmm-yy") -> Oct-26 | J6: =TEXT(J11,"mmm-yy") -> Nov-26 | K6: =TEXT(K11,"mmm-yy") -> Dec-26 | L6: =TEXT(L11,"mmm-yy") -> Jan-27 | M6: =TEXT(M11,"mmm-yy") -> Feb-27 | ... KA6: =TEXT(KA11,"mmm-yy") -> Dec-49
B8: Periods
E10: Start of period | F10: =DATE(2026,7,1) -> 46204 | G10: =F11+1 -> 46235 | H10: =G11+1 -> 46266 | I10: =H11+1 -> 46296 | J10: =I11+1 -> 46327 | K10: =J11+1 -> 46357 | L10: =K11+1 -> 46388 | M10: =L11+1 -> 46419 | N10: =M11+1 -> 46447 | ... KA10: =JZ11+1 -> 54758
E11: End of period | F11: =EOMONTH(F10,0) -> 46234 | G11: =EOMONTH(G10,0) -> 46265 | H11: =EOMONTH(H10,0) -> 46295 | I11: =EOMONTH(I10,0) -> 46326 | J11: =EOMONTH(J10,0) -> 46356 | K11: =EOMONTH(K10,0) -> 46387 | L11: =EOMONTH(L10,0) -> 46418 | M11: =EOMONTH(M10,0) -> 46446 | ... KA11: =EOMONTH(KA10,0) -> 54788
E12: Calendar year | F12: ="CY"&RIGHT(YEAR(F10),2) -> CY26 | G12: ="CY"&RIGHT(YEAR(G10),2) -> CY26 | H12: ="CY"&RIGHT(YEAR(H10),2) -> CY26 | I12: ="CY"&RIGHT(YEAR(I10),2) -> CY26 | J12: ="CY"&RIGHT(YEAR(J10),2) -> CY26 | K12: ="CY"&RIGHT(YEAR(K10),2) -> CY26 | L12: ="CY"&RIGHT(YEAR(L10),2) -> CY27 | M12: ="CY"&RIGHT(YEAR(M10),2) -> CY27 | ... KA12: ="CY"&RIGHT(YEAR(KA10),2) -> CY49
E13: Financial Year | F13: ="FY"&IF(MONTH(F10)>6,RIGHT(YEAR(F10)+1,2),RIGHT(YEAR(F10),2)) -> FY27 | G13: ="FY"&IF(MONTH(G10)>6,RIGHT(YEAR(G10)+1,2),RIGHT(YEAR(G10),2)) -> FY27 | H13: ="FY"&IF(MONTH(H10)>6,RIGHT(YEAR(H10)+1,2),RIGHT(YEAR(H10),2)) -> FY27 | I13: ="FY"&IF(MONTH(I10)>6,RIGHT(YEAR(I10)+1,2),RIGHT(YEAR(I10),2)) -> FY27 | J13: ="FY"&IF(MONTH(J10)>6,RIGHT(YEAR(J10)+1,2),RIGHT(YEAR(J10),2)) -> FY27 | K13: ="FY"&IF(MONTH(K10)>6,RIGHT(YEAR(K10)+1,2),RIGHT(YEAR(K10),2)) -> FY27 | L13: ="FY"&IF(MONTH(L10)>6,RIGHT(YEAR(L10)+1,2),RIGHT(YEAR(L10),2)) -> FY27 | M13: ="FY"&IF(MONTH(M10)>6,RIGHT(YEAR(M10)+1,2),RIGHT(YEAR(M10),2)) -> FY27 | ... KA13: ="FY"&IF(MONTH(KA10)>6,RIGHT(YEAR(KA10)+1,2),RIGHT(YEAR(KA10),2)) -> FY50
E14: Days in Period | F14: =F11-F10+1 -> 31 | G14: =G11-G10+1 -> 31 | H14: =H11-H10+1 -> 30 | I14: =I11-I10+1 -> 31 | J14: =J11-J10+1 -> 30 | K14: =K11-K10+1 -> 31 | L14: =L11-L10+1 -> 31 | M14: =M11-M10+1 -> 28 | ... KA14: =KA11-KA10+1 -> 31
E15: Inflation index
B17: Dates Training
B36: Date Timelines
E53: The main project timeline is provided at the top of this sheet. We are using monthly periods.
E54: The first date uses the DATE function, then all other dates use EOMONTH or the prior month plus 1.
E56: Example:
E57: Start of period | F57: =DATE(2026,7,1) -> 46204 | G57: =F58+1 -> 46235 | H57: =G58+1 -> 46266 | I57: =H58+1 -> 46296
E58: End of period | F58: =EOMONTH(F57,0) -> 46234 | G58: =EOMONTH(G57,0) -> 46265 | H58: =EOMONTH(H57,0) -> 46295 | I58: =EOMONTH(I57,0) -> 46326
E60: Formulas:
E61: Start of period | F61: =_xlfn.FORMULATEXT(F57) -> =DATE(2026,7,1) | G61: =_xlfn.FORMULATEXT(G57) -> =F58+1 | H61: =_xlfn.FORMULATEXT(H57) -> =G58+1 | I61: =_xlfn.FORMULATEXT(I57) -> =H58+1
E62: End of period | F62: =_xlfn.FORMULATEXT(F58) -> =EOMONTH(F57,0) | G62: =_xlfn.FORMULATEXT(G58) -> =EOMONTH(G57,0) | H62: =_xlfn.FORMULATEXT(H58) -> =EOMONTH(H57,0) | I62: =_xlfn.FORMULATEXT(I58) -> =EOMONTH(I57,0)
D64: EOMONTH
E65: EOMONTH also becomes useful if you want to offset by quarter, years, and also if you want to go backwards in time.
E66: The EOMONTH formula always gives the end of the month, so you will need to adjust for any other date as required
E68: Item | F68: Example | G68: FORMULA TEXT
E69: Reference Date | F69: =DATE(2026,7,15) -> 46218 | G69: =_xlfn.FORMULATEXT(F69) -> =DATE(2026,7,15) | H69: =DATE(2026,7,15)
E70: End of current month | F70: =EOMONTH(F69,0) -> 46234 | G70: =_xlfn.FORMULATEXT(F70) -> =EOMONTH(F69,0)
E71: End of quarter | F71: =EOMONTH(F69,2) -> 46295 | G71: =_xlfn.FORMULATEXT(F71) -> =EOMONTH(F69,2) | H71: * assuming reference month is always the start of the quarter
E72: End of quarter (any month) | F72: =EOMONTH(F69,MOD(3-MONTH(F69),3)) -> 46295 | G72: =_xlfn.FORMULATEXT(F72) -> =EOMONTH(F69,MOD(3-MONTH(F69),3)) | H72: * any date within the quarter
E73: Next year | F73: =EOMONTH(F69,12) -> 46599 | G73: =_xlfn.FORMULATEXT(F73) -> =EOMONTH(F69,12)
E74: Start of month | F74: =EOMONTH(F69,-1)+1 -> 46204 | G74: =_xlfn.FORMULATEXT(F74) -> =EOMONTH(F69,-1)+1
D76: DATE
E77: You can also use DATE to achieve similar outcomes, but this can have more complex or longer forumlas.
E78: Item | F78: Example | G78: FORMULA TEXT
E79: Date | F79: =DATE(2026,7,15) -> 46218 | G79: =_xlfn.FORMULATEXT(F79) -> =DATE(2026,7,15)
E80: End of current month | F80: =DATE(YEAR(F79),MONTH(F79)+1,1)-1 -> 46234 | G80: =_xlfn.FORMULATEXT(F80) -> =DATE(YEAR(F79),MONTH(F79)+1,1)-1
E81: End of quarter | F81: =DATE(YEAR(F80),MONTH(F80)+3,1)-1 -> 46295 | G81: =_xlfn.FORMULATEXT(F81) -> =DATE(YEAR(F80),MONTH(F80)+3,1)-1 | H81: * assuming reference month is always the start of the quarter
E82: End of quarter (any month) | F82: =DATE(YEAR(F69),CEILING(MONTH(F69),3)+1,0) -> 46295 | G82: =_xlfn.FORMULATEXT(F82) -> =DATE(YEAR(F69),CEILING(MONTH(F69),3)+1,0) | H82: * any date within the quarter
...

Sheet NPV
B1: Yearly
B2: Period | C2: 0 | D2: =C2+1 -> 1 | E2: =D2+1 -> 2 | F2: =E2+1 -> 3 | G2: =F2+1 -> 4 | H2: =G2+1 -> 5 | I2: =H2+1 -> 6 | J2: =I2+1 -> 7 | K2: =J2+1 -> 8 | ... AA2: =Z2+1 -> 24
B3: Date | C3: =DATE(2026,12,31) -> 46387 | D3: =EOMONTH(C3,12) -> 46752 | E3: =EOMONTH(D3,12) -> 47118 | F3: =EOMONTH(E3,12) -> 47483 | G3: =EOMONTH(F3,12) -> 47848 | H3: =EOMONTH(G3,12) -> 48213 | I3: =EOMONTH(H3,12) -> 48579 | J3: =EOMONTH(I3,12) -> 48944 | K3: =EOMONTH(J3,12) -> 49309 | ... AA3: =EOMONTH(Z3,12) -> 55153
B4: FCF | C4: -1000 | D4: -250 | E4: -100 | F4: 100 | G4: 175 | H4: 250 | I4: 325 | J4: 400 | K4: 400 | L4: 400 | M4: 400 | N4: 400 | O4: 400 | P4: 400 | Q4: 400 | R4: 400 | S4: 400 | T4: 400 | U4: 400 | V4: 400 | W4: 400 | X4: 400 | Y4: 400 | Z4: 400 | AA4: 400
B5: Rate | C5: 0.1
B6: XNPV | C6: =XNPV($C$5,C4:$AA4,C3:$AA3) -> 1073.4182 | D6: =XNPV($C$5,D4:$AA4,D3:$AA3) -> 2280.76 | E6: =XNPV($C$5,E4:$AA4,E3:$AA3) -> 2784.563 | F6: =XNPV($C$5,F4:$AA4,F3:$AA3) -> 3173.0193 | G6: =XNPV($C$5,G4:$AA4,G3:$AA3) -> 3380.3213 | H6: =XNPV($C$5,H4:$AA4,H3:$AA3) -> 3525.8534 | I6: =XNPV($C$5,I4:$AA4,I3:$AA3) -> 3604.3798 | J6: =XNPV($C$5,J4:$AA4,J3:$AA3) -> 3607.3178 | ... AA6: =XNPV($C$5,AA4:$AA4,AA3:$AA3) -> 400
B7: NPV | C7: =NPV($C$5,D4:$AA4)+C4 -> 1075.2192 | D7: =NPV($C$5,E4:$AA4)+D4 -> 2282.7411 | E7: =NPV($C$5,F4:$AA4)+E4 -> 2786.0152 | F7: =NPV($C$5,G4:$AA4)+F4 -> 3174.6167 | G7: =NPV($C$5,H4:$AA4)+G4 -> 3382.0784 | H7: =NPV($C$5,I4:$AA4)+H4 -> 3527.7862 | I7: =NPV($C$5,J4:$AA4)+I4 -> 3605.5648 | J7: =NPV($C$5,K4:$AA4)+J4 -> 3608.6213 | ... Z7: =NPV($C$5,AA4:$AA4)+Z4 -> 763.63636
B9: Manual (days) - PV | C9: =C4 -> -1000 | D9: =D4/(1+$C$5)^((D3-$C$3)/365) -> -227.27273 | E9: =E4/(1+$C$5)^((E3-$C$3)/365) -> -82.62305 | F9: =F4/(1+$C$5)^((F3-$C$3)/365) -> 75.111864 | G9: =G4/(1+$C$5)^((G3-$C$3)/365) -> 119.49615 | H9: =H4/(1+$C$5)^((H3-$C$3)/365) -> 155.1898 | I9: =I4/(1+$C$5)^((I3-$C$3)/365) -> 183.35824 | J9: =J4/(1+$C$5)^((J3-$C$3)/365) -> 205.15608 | K9: =K4/(1+$C$5)^((K3-$C$3)/365) -> 186.50552 | ... AA9: =AA4/(1+$C$5)^((AA3-$C$3)/365) -> 40.546663
B10: Manual (days) - NPV | C10: =SUM(C9:AA9) -> 1073.4182
B11: Check | C11: =C10-C6 -> 0
B12: Manual (periods) - PV | C12: =C4/(1+$C$5)^C2 -> -1000 | D12: =D4/(1+$C$5)^D2 -> -227.27273 | E12: =E4/(1+$C$5)^E2 -> -82.644628 | F12: =F4/(1+$C$5)^F2 -> 75.13148 | G12: =G4/(1+$C$5)^G2 -> 119.52735 | H12: =H4/(1+$C$5)^H2 -> 155.23033 | I12: =I4/(1+$C$5)^I2 -> 183.45403 | J12: =J4/(1+$C$5)^J2 -> 205.26325 | ... AA12: =AA4/(1+$C$5)^AA2 -> 40.610239
B13: Manual (periods) - NPV | C13: =SUM(C12:$AA12) -> 1075.2192
B14: Check | C14: =C13-C7 -> 0
B19: Quarterly
